Workbook

Sheet TA
A1: Technical Assistant Final Duty Roster
A2: =CONCATENATE("Effective from ",TEXT(A3,"d mmmm yyyy")," to ",TEXT(A54,"d mmmm yyyy")) -> Effective from 24 November 2025 to 29 November 2025
A3: 45985
A4: Shift | B4: Time | C4: TechCentre-1 | D4: TechCentre-2 | E4: Rounding-1 | F4: Rounding-2 | G4: Rounding-3 | H4: QC-1 | I4: QC-2
A5: S1 | B5: 0815 - 1030 | C5: Aseel | D5: Nazmir | E5: Srini | F5: Hamdan | H5: Shamiur
A6: S2 | B6: 1030 - 1230 | C6: Srini | D6: Haifa | E6: Awad | F6: Phone | H6: Hamdan
A7: S3 | B7: 1230 - 1430 | C7: Lin Htin | D7: Bismi | E7: Zakarya | F7: Phone | H7: Ebad
A8: S4 | B8: 1430 - 1630 | C8: Michael | D8: Arshia | E8: Lin Htin | F8: Bismi | H8: Yip
A9: S5 | B9: 1630 - 1830 | C9: Hamdan | D9: Haifa | E9: Michael | F9: Arshia | H9: Bismi
A10: S6 | B10: 1830 - 2130 | E10: Zakarya | F10: Donaley | G10: Nahyan | H10: Amr | I10: Irneen
A13: =A3+1 -> 45986
A14: Shift | B14: Time | C14: TechCentre-1 | D14: TechCentre-2 | E14: Rounding-1 | F14: Rounding-2 | G14: Rounding-3 | H14: QC-1 | I14: QC-2
A15: S1 | B15: 0815 - 1030 | C15: Shamiur | D15: Hamdan | E15: Ebad | F15: Donaley | H15: Yip
A16: S2 | B16: 10:30 - 12:30 | C16: Hammad | D16: Umme | E16: Esha | F16: Arshia | H16: Hamdan
A17: S3 | B17: 1230 - 1430 | C17: Valen | D17: Nazmir | E17: Umme | F17: Haifa | H17: Raghad
A18: S4 | B18: 1430 - 1630 | C18: Raghad | D18: Haifa | E18: Lin Htin | F18: Phone | H18: Bismi
A19: S5 | B19: 1630 - 1810 | C19: Hamdan | D19: Lin Htin | E19: Raghad | F19: Bismi | H19: Haifa
B20: 1810 - 1830
A21: S6 | B21: 1830 - 2130
A24: =A13+1 -> 45987
A25: Shift | B25: Time | C25: TechCentre-1 | D25: TechCentre-2 | E25: Rounding-1 | F25: Rounding-2 | G25: Rounding-3 | H25: QC-1 | I25: QC-2
A26: S1 | B26: 0815 - 1030 | C26: Nazmir | D26: Srini | E26: Shamiur | F26: Amr Khaled | H26: Irneen
A27: S2 | B27: 1030 - 1230 | C27: Umme | D27: Esha | E27: Lin Htin | F27: Bismi | H27: Amr Khaled
A28: S3 | B28: 1230 - 1430 | C28: Raghad | D28: Lin Htin | E28: Amr Khaled | F28: Phone | H28: Esha
A29: S4 | B29: 1430 - 1630 | C29: Haifa | D29: Amr Khaled | E29: Donaley | F29: Omar | H29: Lin Htin
A30: S5 | B30: 1630 - 1830 | C30: Ramiz | D30: Arshia | E30: Haifa | F30: Douaa | H30: Amr
A31: S6 | B31: 1830 - 2130 | E31: Akla | F31: Omar Saeed | G31: Zakarya | H31: Ramiz | I31: Haifa
A34: =A24+1 -> 45988
A35: Shift | B35: Time | C35: TechCentre-1 | D35: TechCentre-2 | E35: Rounding-1 | F35: Rounding-2 | G35: Rounding-3 | H35: QC-1 | I35: QC-2
A36: S1 | B36: 0815 - 1030 | C36: Ebad | D36: Donaley | E36: Irneen | H36: Hamdan
A37: S2 | B37: 1030 - 1230 | C37: Hammad | D37: Abrar | E37: Eanan | F37: Arshia | H37: Arsheyan
A38: S3 | B38: 1230 - 1430 | C38: Umme | D38: Amr Khaled | E38: Nazmir | F38: Zakarya | H38: Abrar
A39: S4 | B39: 1430 - 1630 | C39: Eanan | D39: Raghad | E39: Michael | F39: Amr Khaled | H39: Hamdan
A40: S5 | B40: 1630 - 1830 | C40: Michael | D40: Hamdan | E40: Haifa | F40: Ebad | H40: Arshia
A41: S6 | B41: 1830 - 2130 | E41: Akla | F41: Sazid | G41: Nahyan | H41: Michael
A44: =A34+1 -> 45989
A45: Shift | B45: Time | C45: TechCentre-1 | D45: TechCentre-2 | E45: Rounding-1 | F45: Rounding-2 | G45: Rounding-3 | H45: QC-1 | I45: QC-2
A46: S1 | B46: 0815 - 1030 | C46: Raghad | D46: Amr Khaled | E46: Donaley | F46: Douaa | H46: Valen
A47: S2 | B47: 1030 - 1230 | C47: Michael | D47: Abrar | E47: Esha | F47: Raghad | H47: Eanan
A48: S3 | B48: 1230 - 1430 | C48: Umme | D48: Shukri | E48: Valen | F48: Phone | H48: Raghad
...

Sheet Trainee
A1: Technical Assistant Trainee Final Duty Roster
A2: =CONCATENATE("Effective from ",TEXT(A3,"d mmmm yyyy")," to ",TEXT(A54,"d mmmm yyyy")) -> Effective from 3 November 2025 to 8 November 2025
A3: 45964
A4: Shift | B4: Time | C4: TechCentre-1 | D4: TechCentre-2 | E4: Rounding-1 | F4: Rounding-2 | H4: QC-1 | I4: QC-2
A5: S1 | B5: 0815 - 1030 | C5: Sriniketan Parthasarathi | D5: MOHAMED AWAD MOHAMED ABDELRAHIM | E5: Nazeer Fathima Akla | F5: HAN THU HTUN | H5: VALENCIA AGNETA HARIANSJAH GOUW | I5: HAIFA MOHAMED SHIRAZ
A6: S2 | B6: 1030 - 1230 | C6: Umme Ashfakum Maney | D6: HAN THU HTUN | E6: ANIK HASAN | F6: MOHAMED AWAD MOHAMED ABDELRAHIM | H6: Sriniketan Parthasarathi | I6: DOUAA MAGUINI
A7: S3 | B7: 1230 - 1430 | C7: ANIK HASAN | D7: NYAN LIN HTET | E7: PHONE MYAT MIN | F7: LIN HTIN AUNG | H7: Muhammad Usman | I7: Zakarya Hussein Bin Askar
A8: S4 | B8: 1430 - 1630 | C8: FATMA JEMAL MOHAMED | D8: ESHA TARIQ WANT | E8: ONG YUEN NING | F8: MUHAMMAD ABDULLAH TAHIR | H8: LIN HTIN AUNG | I8: HAN THU HTUN
A9: S5 | B9: 1630 - 1830 | C9: VALENCIA AGNETA HARIANSJAH GOUW | D9: DOUAA MAGUINI | E9: MD.KABIDUZZAMAN | F9: HAIFA MOHAMED SHIRAZ | H9: ARSHIA BARI | I9: FAHEEM AHMED
A10: S6 | B10: 1830 - 2130 | C10: No Slot | E10: FAHEEM AHMED | F10: ESHA TARIQ WANT | H10: OMAR SAEED MOHAMMED AL-SULTAN | I10: ONG YUEN NING
A13: =A3+1 -> 45965
A14: Shift | B14: Time | C14: =C4 -> TechCentre-1 | D14: =D4 -> TechCentre-2 | E14: =E4 -> Rounding-1 | F14: =F4 -> Rounding-2 | H14: =H4 -> QC-1 | I14: =I4 -> QC-2
A15: S1 | B15: 0815 - 1030 | C15: ONG YUEN NING | D15: LUJAIN ISMAIL ELBAGIR HUSAIN | E15: MUHAMMAD NAZMIR BIN NOR AZLAN | F15: CHONG JIA YUN | G15: Total Shifts | H15: MD.KABIDUZZAMAN | I15: MOHAMED IRNEEN AHMED
A16: S2 | B16: 1030 - 1230 | C16: ESHA TARIQ WANT | D16: Umme Ashfakum Maney | E16: JANNATUL FERDOUS BISMI | F16: ONG YUEN NING | G16: Total Shifts | H16: ANIK HASAN | I16: CHONG JIA YUN
A17: S3 | B17: 1230 - 1430 | C17: MUHAMMAD ABDULLAH TAHIR | D17: Sriniketan Parthasarathi | E17: BRANDON GO | F17: DOUAA MAGUINI | G17: Total Shifts | H17: ESHA TARIQ WANT | I17: FATMA JEMAL MOHAMED
A18: S4 | B18: 1430 - 1630 | C18: FAHEEM AHMED | D18: LIN HTIN AUNG | E18: MUHAMMAD NAZMIR BIN NOR AZLAN | F18: Sriniketan Parthasarathi | G18: Total Shifts | H18: JANNATUL FERDOUS BISMI | I18: Zakarya Hussein Bin Askar
A19: S5 | B19: 1630 - 1810 | C19: Zakarya Hussein Bin Askar | D19: Nazeer Fathima Akla | E19: MOHAMED AWAD MOHAMED ABDELRAHIM | F19: JANNATUL FERDOUS BISMI | G19: Total Shifts | H19: Umme Ashfakum Maney | I19: Sriniketan Parthasarathi
B20: 1810 - 1830
A21: S6 | B21: 1830 - 2130 | C21: No Slot
A24: =A13+1 -> 45966
A25: Shift | B25: Time | C25: =C4 -> TechCentre-1 | D25: =D4 -> TechCentre-2 | E25: =E4 -> Rounding-1 | F25: =F4 -> Rounding-2 | H25: =H4 -> QC-1 | I25: =I4 -> QC-2
A26: S1 | B26: 0815 - 1030 | C26: MD.KABIDUZZAMAN | D26: PHONE MYAT MIN | E26: VALENCIA AGNETA HARIANSJAH GOUW | F26: Nazeer Fathima Akla | H26: Sriniketan Parthasarathi | I26: ARSHIA BARI
A27: S2 | B27: 1030 - 1230 | C27: OMAR SAEED MOHAMMED AL-SULTAN | D27: ESHA TARIQ WANT | E27: Umme Ashfakum Maney | F27: FATMA JEMAL MOHAMED | H27: Nazeer Fathima Akla | I27: MUHAMMAD ABDULLAH TAHIR
A28: S3 | B28: 1230 - 1430 | C28: MUHAMMAD ABDULLAH TAHIR | D28: MD.KABIDUZZAMAN | E28: ESHA TARIQ WANT | F28: JANNATUL FERDOUS BISMI | H28: MD AL NAHYAN | I28: OMAR SAEED MOHAMMED AL-SULTAN
A29: S4 | B29: 1430 - 1630 | C29: Muhammad Usman | D29: HAN THU HTUN | E29: MD AL NAHYAN | F29: Sriniketan Parthasarathi | H29: HAIFA MOHAMED SHIRAZ | I29: VALENCIA AGNETA HARIANSJAH GOUW
A30: S5 | B30: 1630 - 1830 | C30: JANNATUL FERDOUS BISMI | D30: Sriniketan Parthasarathi | E30: GONG JAC YIK | F30: NYAN LIN HTET | H30: ESHA TARIQ WANT | I30: BRANDON GO
A31: S6 | B31: 1830 - 2130 | C31: No Slot | E31: RABII BOUDHINA | F31: MUHAMMAD ABDULLAH TAHIR | H31: Nazeer Fathima Akla | I31: JANNATUL FERDOUS BISMI
J32: 2
A34: =A24+1 -> 45967
A35: Shift | B35: Time | C35: =C4 -> TechCentre-1 | D35: =D4 -> TechCentre-2 | E35: =E4 -> Rounding-1 | F35: =F4 -> Rounding-2 | H35: =H4 -> QC-1 | I35: =I4 -> QC-2
A36: S1 | B36: 0815 - 1030 | C36: MUHAMMAD NAZMIR BIN NOR AZLAN | D36: HAMZAH ABDELSALAM ELMEDAKA | E36: LUJAIN ISMAIL ELBAGIR HUSAIN | F36: RABII BOUDHINA | H36: CHONG JIA YUN | I36: MOHAMED IRNEEN AHMED
A37: S2 | B37: 1030 - 1230 | C37: MUHAMMAD ABDULLAH TAHIR | D37: BRANDON GO | E37: HAMZAH ABDELSALAM ELMEDAKA | F37: ONG YUEN NING | H37: LIN HTIN AUNG | I37: MUHAMMAD NAZMIR BIN NOR AZLAN
A38: S3 | B38: 1230 - 1430 | C38: ARSHIA BARI | D38: MD AL NAHYAN | E38: OMAR SAEED MOHAMMED AL-SULTAN | F38: Nazeer Fathima Akla | H38: MUHAMMAD ABDULLAH TAHIR | I38: Umme Ashfakum Maney
A39: S4 | B39: 1430 - 1630 | C39: CHONG JIA YUN | D39: LUJAIN ISMAIL ELBAGIR HUSAIN | E39: LIN HTIN AUNG | F39: ARSHIA BARI | H39: MUHAMMAD NAZMIR BIN NOR AZLAN | I39: MD SAFAT ZUBAYER
A40: S5 | B40: 1630 - 1830 | C40: BRANDON GO | D40: MUHAMMAD NAZMIR BIN NOR AZLAN | E40: FATMA JEMAL MOHAMED | F40: Umme Ashfakum Maney | H40: RABII BOUDHINA | I40: FAHEEM AHMED
A41: S6 | B41: 1830 - 2130 | C41: No Slot | E41: MD.KABIDUZZAMAN | F41: HAIFA MOHAMED SHIRAZ | H41: ARSHIA BARI | I41: HAMZAH ABDELSALAM ELMEDAKA
A44: =A34+1 -> 45968
A45: Shift | B45: Time | C45: =C4 -> TechCentre-1 | D45: =D4 -> TechCentre-2 | E45: =E4 -> Rounding-1 | F45: =F4 -> Rounding-2 | H45: =H4 -> QC-1 | I45: =I4 -> QC-2
A46: S1 | B46: 0815 - 1030 | C46: Nazeer Fathima Akla | D46: MOHAMED AWAD MOHAMED ABDELRAHIM | E46: HAMZAH ABDELSALAM ELMEDAKA | F46: CHONG JIA YUN | H46: PHONE MYAT MIN | I46: MD.KABIDUZZAMAN
A47: S2 | B47: 1030 - 1230 | C47: RABII BOUDHINA | D47: MD SAFAT ZUBAYER | E47: MOHAMED IRNEEN AHMED | F47: PHONE MYAT MIN | H47: FATMA JEMAL MOHAMED | I47: MOHAMED AWAD MOHAMED ABDELRAHIM
...

Sheet Names list
B1: TA name | C1: Preferred name | D1: Email | E1: Column1 | F1: Column2
B2: Abdulla Meesum Ahmed | C2: Meesum | D2: abdulla.meesum@cloudmails.apu.edu.my | E2: TA
B3: Ahmed Mazin Mahir | C3: Mazin | D3: ahmed.mazin@cloudmails.apu.edu.my | E3: TA
B4: Amr Nezar Mohamed Ali | C4: Amr | D4: amr.nezar@cloudmails.apu.edu.my | E4: TA
B5: Arsheyan Ibn Ehtesham | C5: Arsheyan | D5: arsheyan.ehtesham@cloudmails.apu.edu.my | E5: TA
B6: Ashar Sayeed | C6: Ashar | D6: ashar.sayeed@cloudmails.apu.edu.my | E6: TA
B7: Aseel Mohammed Hassan Sanad | C7: Aseel | D7: aseel.sanad.ta@mail.apu.edu.my | E7: TA
B8: Chennupati Sai Dheeraj | C8: Sai | D8: chennupati.sai@cloudmails.apu.edu.my | E8: TA
B9: Clairine Allegra Muliono | C9: Clairine | D9: clairine.allegra.ta@mail.apu.edu.my | E9: TA
B10: Eanan Anjum | C10: Eanan | D10: eanan.anjum.ta@mail.apu.edu.my | E10: TA
B11: Ebad Ejaz Fakih | C11: Ebad | D11: ebad.ejaz.ta@mail.apu.edu.my | E11: TA
B12: Evelyn Angelica Lie | C12: Evelyn | D12: evelyn.angelica.ta@mail.apu.edu.my | E12: TA
B13: Farah Wesam Mohammad Alali | C13: Farah | D13: farah.wesam@cloudmails.apu.edu.my | E13: TA
... B69: Zakarya Hussein Bin Askar | C69: Zakarya | D69: zakarya.hussein.ta@mail.apu.edu.my | E69: TA
C70: Public Holiday
C71: No Slot
O75: Description | P75: Shifts
O76: Normal shifts (2 Hour) | P76: 150 | Q76: 300
O77: Night Shift (S6, 3 Hours) | P77: 16 | Q77: 48
O78: Saturday Shift (5 Hours) | P78: 4 | Q78: 20
C79: Inactive | D79: Trainee Total : 54
D80: October Trainee 2025 | G80: TechCentre | H80: Rounding | I80: QC | J80: Total shifts | K80: Total Hours | M80: Saturday TechCentre | N80: Saturday Rounding | O80: S6 Rounding | P80: S6 QC
C81: AHMAD ARSAL KHAN | G81: =COUNTIFS(Trainee!$C$5:$C$57, C81) + COUNTIFS(Trainee!$D$5:$D$51, C81) -> 0 | H81: =COUNTIFS(Trainee!$E$5:$F$51, C81) + COUNTIFS(Trainee!$D$56:$D$57, C81) -> 0 | I81: =COUNTIF(Trainee!$H$5:$I$51, C81) -> 0 | J81: =SUM(G81) + (H81) +(I81) -> 0 | K81: =SUM(MAX(G81 - M81, 0)*2 + MAX(H81 - N81 - O81, 0)*2 + MAX(I81 - P81, 0)*2 + M81*5 + N81*5 + O81*3 + P81*3) -> 0 | M81: =COUNTIF(Trainee!$C$56:$C$59, C81) -> 0 | N81: =COUNTIF(Trainee!$D$56:$D$57, C81) -> 0 | O81: =COUNTIFS(Trainee!$E$10:$F$10, C81) + COUNTIFS(Trainee!$E$31:$F$31, C81) + COUNTIFS(Trainee!$E$41:$F$41, C81) + COUNTIFS(Trainee!$E$51:$F51, C81) -> 0 | P81: =COUNTIFS(Trainee!$H$10:$I$10, C81) + COUNTIFS(Trainee!$H$31:$I$31, C81) + COUNTIFS(Trainee!$H$41:$I$41, C81) + COUNTIFS(Trainee!$H$51:$I51, C81) -> 0
C82: AMOS ROSH | G82: =COUNTIFS(Trainee!$C$5:$C$57, C82) + COUNTIFS(Trainee!$D$5:$D$51, C82) -> 0 | H82: =COUNTIFS(Trainee!$E$5:$F$51, C82) + COUNTIFS(Trainee!$D$56:$D$57, C82) -> 0 | I82: =COUNTIF(Trainee!$H$5:$I$51, C82) -> 0 | J82: =SUM(G82) + (H82) +(I82) -> 0 | K82: =SUM(MAX(G82 - M82, 0)*2 + MAX(H82 - N82 - O82, 0)*2 + MAX(I82 - P82, 0)*2 + M82*5 + N82*5 + O82*3 + P82*3) -> 0 | M82: =COUNTIF(Trainee!$C$56:$C$57, C82) -> 0 | N82: =COUNTIF(Trainee!$D$56:$D$57, C82) -> 0 | O82: =COUNTIFS(Trainee!$E$10:$F$10, C82) + COUNTIFS(Trainee!$E$31:$F$31, C82) + COUNTIFS(Trainee!$E$41:$F$41, C82) + COUNTIFS(Trainee!$E$51:$F52, C82) -> 0 | P82: =COUNTIFS(Trainee!$H$10:$I$10, C82) + COUNTIFS(Trainee!$H$31:$I$31, C82) + COUNTIFS(Trainee!$H$41:$I$41, C82) + COUNTIFS(Trainee!$H$51:$I52, C82) -> 0
C83: AMR KHALED HAMID ANAAM | G83: =COUNTIFS(Trainee!$C$5:$C$57, C83) + COUNTIFS(Trainee!$D$5:$D$51, C83) -> 0 | H83: =COUNTIFS(Trainee!$E$5:$F$51, C83) + COUNTIFS(Trainee!$D$56:$D$57, C83) -> 0 | I83: =COUNTIF(Trainee!$H$5:$I$51, C83) -> 0 | J83: =SUM(G83) + (H83) +(I83) -> 0 | K83: =SUM(MAX(G83 - M83, 0)*2 + MAX(H83 - N83 - O83, 0)*2 + MAX(I83 - P83, 0)*2 + M83*5 + N83*5 + O83*3 + P83*3) -> 0 | M83: =COUNTIF(Trainee!$C$56:$C$57, C83) -> 0 | N83: =COUNTIF(Trainee!$D$56:$D$59, C83) -> 0 | O83: =COUNTIFS(Trainee!$E$10:$F$10, C83) + COUNTIFS(Trainee!$E$31:$F$31, C83) + COUNTIFS(Trainee!$E$41:$F$41, C83) + COUNTIFS(Trainee!$E$51:$F53, C83) -> 0 | P83: =COUNTIFS(Trainee!$H$10:$I$10, C83) + COUNTIFS(Trainee!$H$31:$I$31, C83) + COUNTIFS(Trainee!$H$41:$I$41, C83) + COUNTIFS(Trainee!$H$51:$I53, C83) -> 0
C84: ANAS AHMED SYED | G84: =COUNTIFS(Trainee!$C$5:$C$57, C84) + COUNTIFS(Trainee!$D$5:$D$51, C84) -> 0 | H84: =COUNTIFS(Trainee!$E$5:$F$51, C84) + COUNTIFS(Trainee!$D$56:$D$57, C84) -> 0 | I84: =COUNTIF(Trainee!$H$5:$I$51, C84) -> 0 | J84: =SUM(G84) + (H84) +(I84) -> 0 | K84: =SUM(MAX(G84 - M84, 0)*2 + MAX(H84 - N84 - O84, 0)*2 + MAX(I84 - P84, 0)*2 + M84*5 + N84*5 + O84*3 + P84*3) -> 0 | M84: =COUNTIF(Trainee!$C$56:$C$57, C84) -> 0 | N84: =COUNTIF(Trainee!$D$56:$D$57, C84) -> 0 | O84: =COUNTIFS(Trainee!$E$10:$F$10, C84) + COUNTIFS(Trainee!$E$31:$F$31, C84) + COUNTIFS(Trainee!$E$41:$F$41, C84) + COUNTIFS(Trainee!$E$51:$F54, C84) -> 0 | P84: =COUNTIFS(Trainee!$H$10:$I$10, C84) + COUNTIFS(Trainee!$H$31:$I$31, C84) + COUNTIFS(Trainee!$H$41:$I$41, C84) + COUNTIFS(Trainee!$H$51:$I53, C84) -> 0
C85: ANIK HASAN | G85: =COUNTIFS(Trainee!$C$5:$C$57, C85) + COUNTIFS(Trainee!$D$5:$D$51, C85) -> 1 | H85: =COUNTIFS(Trainee!$E$5:$F$51, C85) + COUNTIFS(Trainee!$D$56:$D$57, C85) -> 1 | I85: =COUNTIF(Trainee!$H$5:$I$51, C85) -> 1 | J85: =SUM(G85) + (H85) +(I85) -> 3 | K85: =SUM(MAX(G85 - M85, 0)*2 + MAX(H85 - N85 - O85, 0)*2 + MAX(I85 - P85, 0)*2 + M85*5 + N85*5 + O85*3 + P85*3) -> 6 | M85: =COUNTIF(Trainee!$C$56:$C$57, C85) -> 0 | N85: =COUNTIF(Trainee!$D$56:$D$57, C85) -> 0 | O85: =COUNTIFS(Trainee!$E$10:$F$10, C85) + COUNTIFS(Trainee!$E$31:$F$31, C85) + COUNTIFS(Trainee!$E$41:$F$41, C85) + COUNTIFS(Trainee!$E$51:$F55, C85) -> 0 | P85: =COUNTIFS(Trainee!$H$10:$I$10, C85) + COUNTIFS(Trainee!$H$31:$I$31, C85) + COUNTIFS(Trainee!$H$41:$I$41, C85) + COUNTIFS(Trainee!$H$51:$I53, C85) -> 0
C86: ARSHIA BARI | G86: =COUNTIFS(Trainee!$C$5:$C$57, C86) + COUNTIFS(Trainee!$D$5:$D$51, C86) -> 2 | H86: =COUNTIFS(Trainee!$E$5:$F$51, C86) + COUNTIFS(Trainee!$D$56:$D$59, C86) -> 2 | I86: =COUNTIF(Trainee!$H$5:$I$51, C86) -> 3 | J86: =SUM(G86) + (H86) +(I86) -> 7 | K86: =SUM(MAX(G86 - M86, 0)*2 + MAX(H86 - N86 - O86, 0)*2 + MAX(I86 - P86, 0)*2 + M86*5 + N86*5 + O86*3 + P86*3) -> 15 | M86: =COUNTIF(Trainee!$C$56:$C$57, C86) -> 0 | N86: =COUNTIF(Trainee!$D$56:$D$57, C86) -> 0 | O86: =COUNTIFS(Trainee!$E$10:$F$10, C86) + COUNTIFS(Trainee!$E$31:$F$31, C86) + COUNTIFS(Trainee!$E$41:$F$41, C86) + COUNTIFS(Trainee!$E$51:$F56, C86) -> 0 | P86: =COUNTIFS(Trainee!$H$10:$I$10, C86) + COUNTIFS(Trainee!$H$31:$I$31, C86) + COUNTIFS(Trainee!$H$41:$I$41, C86) + COUNTIFS(Trainee!$H$51:$I53, C86) -> 1
C87: BRANDON GO | G87: =COUNTIFS(Trainee!$C$5:$C$57, C87) + COUNTIFS(Trainee!$D$5:$D$51, C87) -> 2 | H87: =COUNTIFS(Trainee!$E$5:$F$51, C87) + COUNTIFS(Trainee!$D$56:$D$57, C87) -> 1 | I87: =COUNTIF(Trainee!$H$5:$I$51, C87) -> 1 | J87: =SUM(G87) + (H87) +(I87) -> 4 | K87: =SUM(MAX(G87 - M87, 0)*2 + MAX(H87 - N87 - O87, 0)*2 + MAX(I87 - P87, 0)*2 + M87*5 + N87*5 + O87*3 + P87*3) -> 8 | M87: =COUNTIF(Trainee!$C$56:$C$57, C87) -> 0 | N87: =COUNTIF(Trainee!$D$56:$D$57, C87) -> 0 | O87: =COUNTIFS(Trainee!$E$10:$F$10, C87) + COUNTIFS(Trainee!$E$31:$F$31, C87) + COUNTIFS(Trainee!$E$41:$F$41, C87) + COUNTIFS(Trainee!$E$51:$F57, C87) -> 0 | P87: =COUNTIFS(Trainee!$H$10:$I$10, C87) + COUNTIFS(Trainee!$H$31:$I$31, C87) + COUNTIFS(Trainee!$H$41:$I$41, C87) + COUNTIFS(Trainee!$H$51:$I53, C87) -> 0
C88: CHONG JIA YUN | G88: =COUNTIFS(Trainee!$C$5:$C$57, C88) + COUNTIFS(Trainee!$D$5:$D$51, C88) -> 1 | H88: =COUNTIFS(Trainee!$E$5:$F$51, C88) + COUNTIFS(Trainee!$D$56:$D$57, C88) -> 3 | I88: =COUNTIF(Trainee!$H$5:$I$51, C88) -> 2 | J88: =SUM(G88) + (H88) +(I88) -> 6 | K88: =SUM(MAX(G88 - M88, 0)*2 + MAX(H88 - N88 - O88, 0)*2 + MAX(I88 - P88, 0)*2 + M88*5 + N88*5 + O88*3 + P88*3) -> 12 | M88: =COUNTIF(Trainee!$C$56:$C$57, C88) -> 0 | N88: =COUNTIF(Trainee!$D$56:$D$57, C88) -> 0 | O88: =COUNTIFS(Trainee!$E$10:$F$10, C88) + COUNTIFS(Trainee!$E$31:$F$31, C88) + COUNTIFS(Trainee!$E$41:$F$41, C88) + COUNTIFS(Trainee!$E$51:$F58, C88) -> 0 | P88: =COUNTIFS(Trainee!$H$10:$I$10, C88) + COUNTIFS(Trainee!$H$31:$I$31, C88) + COUNTIFS(Trainee!$H$41:$I$41, C88) + COUNTIFS(Trainee!$H$51:$I53, C88) -> 0
C89: CHUA YI HUA | G89: =COUNTIFS(Trainee!$C$5:$C$57, C89) + COUNTIFS(Trainee!$D$5:$D$51, C89) -> 0 | H89: =COUNTIFS(Trainee!$E$5:$F$51, C89) + COUNTIFS(Trainee!$D$56:$D$57, C89) -> 0 | I89: =COUNTIF(Trainee!$H$5:$I$51, C89) -> 0 | J89: =SUM(G89) + (H89) +(I89) -> 0 | K89: =SUM(MAX(G89 - M89, 0)*2 + MAX(H89 - N89 - O89, 0)*2 + MAX(I89 - P89, 0)*2 + M89*5 + N89*5 + O89*3 + P89*3) -> 0 | M89: =COUNTIF(Trainee!$C$56:$C$57, C89) -> 0 | N89: =COUNTIF(Trainee!$D$56:$D$57, C89) -> 0 | O89: =COUNTIFS(Trainee!$E$10:$F$10, C89) + COUNTIFS(Trainee!$E$31:$F$31, C89) + COUNTIFS(Trainee!$E$41:$F$41, C89) + COUNTIFS(Trainee!$E$51:$F59, C89) -> 0 | P89: =COUNTIFS(Trainee!$H$10:$I$10, C89) + COUNTIFS(Trainee!$H$31:$I$31, C89) + COUNTIFS(Trainee!$H$41:$I$41, C89) + COUNTIFS(Trainee!$H$51:$I59, C89) -> 0
C90: DONALEY MAKARAWA | G90: =COUNTIFS(Trainee!$C$5:$C$57, C90) + COUNTIFS(Trainee!$D$5:$D$51, C90) -> 0 | H90: =COUNTIFS(Trainee!$E$5:$F$51, C90) + COUNTIFS(Trainee!$D$56:$D$57, C90) -> 0 | I90: =COUNTIF(Trainee!$H$5:$I$51, C90) -> 0 | J90: =SUM(G90) + (H90) +(I90) -> 0 | K90: =SUM(MAX(G90 - M90, 0)*2 + MAX(H90 - N90 - O90, 0)*2 + MAX(I90 - P90, 0)*2 + M90*5 + N90*5 + O90*3 + P90*3) -> 0 | M90: =COUNTIF(Trainee!$C$56:$C$57, C90) -> 0 | N90: =COUNTIF(Trainee!$D$56:$D$57, C90) -> 0 | O90: =COUNTIFS(Trainee!$E$10:$F$10, C90) + COUNTIFS(Trainee!$E$31:$F$31, C90) + COUNTIFS(Trainee!$E$41:$F$41, C90) + COUNTIFS(Trainee!$E$51:$F60, C90) -> 0 | P90: =COUNTIFS(Trainee!$H$10:$I$10, C90) + COUNTIFS(Trainee!$H$31:$I$31, C90) + COUNTIFS(Trainee!$H$41:$I$41, C90) + COUNTIFS(Trainee!$H$51:$I60, C90) -> 0
C91: DOUAA MAGUINI | G91: =COUNTIFS(Trainee!$C$5:$C$57, C91) + COUNTIFS(Trainee!$D$5:$D$51, C91) -> 1 | H91: =COUNTIFS(Trainee!$E$5:$F$51, C91) + COUNTIFS(Trainee!$D$56:$D$57, C91) -> 1 | I91: =COUNTIF(Trainee!$H$5:$I$51, C91) -> 1 | J91: =SUM(G91) + (H91) +(I91) -> 3 | K91: =SUM(MAX(G91 - M91, 0)*2 + MAX(H91 - N91 - O91, 0)*2 + MAX(I91 - P91, 0)*2 + M91*5 + N91*5 + O91*3 + P91*3) -> 6 | M91: =COUNTIF(Trainee!$C$56:$C$57, C91) -> 0 | N91: =COUNTIF(Trainee!$D$56:$D$57, C91) -> 0 | O91: =COUNTIFS(Trainee!$E$10:$F$10, C91) + COUNTIFS(Trainee!$E$31:$F$31, C91) + COUNTIFS(Trainee!$E$41:$F$41, C91) + COUNTIFS(Trainee!$E$51:$F61, C91) -> 0 | P91: =COUNTIFS(Trainee!$H$10:$I$10, C91) + COUNTIFS(Trainee!$H$31:$I$31, C91) + COUNTIFS(Trainee!$H$41:$I$41, C91) + COUNTIFS(Trainee!$H$51:$I61, C91) -> 0
C92: ESHA TARIQ WANT | G92: =COUNTIFS(Trainee!$C$5:$C$57, C92) + COUNTIFS(Trainee!$D$5:$D$51, C92) -> 3 | H92: =COUNTIFS(Trainee!$E$5:$F$51, C92) + COUNTIFS(Trainee!$D$56:$D$57, C92) -> 2 | I92: =COUNTIF(Trainee!$H$5:$I$51, C92) -> 2 | J92: =SUM(G92) + (H92) +(I92) -> 7 | K92: =SUM(MAX(G92 - M92, 0)*2 + MAX(H92 - N92 - O92, 0)*2 + MAX(I92 - P92, 0)*2 + M92*5 + N92*5 + O92*3 + P92*3) -> 15 | M92: =COUNTIF(Trainee!$C$56:$C$57, C92) -> 0 | N92: =COUNTIF(Trainee!$D$56:$D$57, C92) -> 0 | O92: =COUNTIFS(Trainee!$E$10:$F$10, C92) + COUNTIFS(Trainee!$E$31:$F$31, C92) + COUNTIFS(Trainee!$E$41:$F$41, C92) + COUNTIFS(Trainee!$E$51:$F62, C92) -> 1 | P92: =COUNTIFS(Trainee!$H$10:$I$10, C92) + COUNTIFS(Trainee!$H$31:$I$31, C92) + COUNTIFS(Trainee!$H$41:$I$41, C92) + COUNTIFS(Trainee!$H$51:$I62, C92) -> 0
C93: FAHEEM AHMED | G93: =COUNTIFS(Trainee!$C$5:$C$57, C93) + COUNTIFS(Trainee!$D$5:$D$51, C93) -> 1 | H93: =COUNTIFS(Trainee!$E$5:$F$51, C93) + COUNTIFS(Trainee!$D$56:$D$57, C93) -> 1 | I93: =COUNTIF(Trainee!$H$5:$I$51, C93) -> 2 | J93: =SUM(G93) + (H93) +(I93) -> 4 | K93: =SUM(MAX(G93 - M93, 0)*2 + MAX(H93 - N93 - O93, 0)*2 + MAX(I93 - P93, 0)*2 + M93*5 + N93*5 + O93*3 + P93*3) -> 9 | M93: =COUNTIF(Trainee!$C$56:$C$57, C93) -> 0 | N93: =COUNTIF(Trainee!$D$56:$D$57, C93) -> 0 | O93: =COUNTIFS(Trainee!$E$10:$F$10, C93) + COUNTIFS(Trainee!$E$31:$F$31, C93) + COUNTIFS(Trainee!$E$41:$F$41, C93) + COUNTIFS(Trainee!$E$51:$F63, C93) -> 1 | P93: =COUNTIFS(Trainee!$H$10:$I$10, C93) + COUNTIFS(Trainee!$H$31:$I$31, C93) + COUNTIFS(Trainee!$H$41:$I$41, C93) + COUNTIFS(Trainee!$H$51:$I63, C93) -> 0
C94: FATMA JEMAL MOHAMED | G94: =COUNTIFS(Trainee!$C$5:$C$57, C94) + COUNTIFS(Trainee!$D$5:$D$51, C94) -> 1 | H94: =COUNTIFS(Trainee!$E$5:$F$51, C94) + COUNTIFS(Trainee!$D$56:$D$57, C94) -> 2 | I94: =COUNTIF(Trainee!$H$5:$I$51, C94) -> 3 | J94: =SUM(G94) + (H94) +(I94) -> 6 | K94: =SUM(MAX(G94 - M94, 0)*2 + MAX(H94 - N94 - O94, 0)*2 + MAX(I94 - P94, 0)*2 + M94*5 + N94*5 + O94*3 + P94*3) -> 12 | M94: =COUNTIF(Trainee!$C$56:$C$57, C94) -> 0 | N94: =COUNTIF(Trainee!$D$56:$D$57, C94) -> 0 | O94: =COUNTIFS(Trainee!$E$10:$F$10, C94) + COUNTIFS(Trainee!$E$31:$F$31, C94) + COUNTIFS(Trainee!$E$41:$F$41, C94) + COUNTIFS(Trainee!$E$51:$F64, C94) -> 0 | P94: =COUNTIFS(Trainee!$H$10:$I$10, C94) + COUNTIFS(Trainee!$H$31:$I$31, C94) + COUNTIFS(Trainee!$H$41:$I$41, C94) + COUNTIFS(Trainee!$H$51:$I64, C94) -> 0
C95: GILBERT LAIS | G95: =COUNTIFS(Trainee!$C$5:$C$57, C95) + COUNTIFS(Trainee!$D$5:$D$51, C95) -> 0 | H95: =COUNTIFS(Trainee!$E$5:$F$51, C95) + COUNTIFS(Trainee!$D$56:$D$57, C95) -> 0 | I95: =COUNTIF(Trainee!$H$5:$I$51, C95) -> 0 | J95: =SUM(G95) + (H95) +(I95) -> 0 | K95: =SUM(MAX(G95 - M95, 0)*2 + MAX(H95 - N95 - O95, 0)*2 + MAX(I95 - P95, 0)*2 + M95*5 + N95*5 + O95*3 + P95*3) -> 0 | M95: =COUNTIF(Trainee!$C$56:$C$57, C95) -> 0 | N95: =COUNTIF(Trainee!$D$56:$D$57, C95) -> 0 | O95: =COUNTIFS(Trainee!$E$10:$F$10, C95) + COUNTIFS(Trainee!$E$31:$F$31, C95) + COUNTIFS(Trainee!$E$41:$F$41, C95) + COUNTIFS(Trainee!$E$51:$F65, C95) -> 0 | P95: =COUNTIFS(Trainee!$H$10:$I$10, C95) + COUNTIFS(Trainee!$H$31:$I$31, C95) + COUNTIFS(Trainee!$H$41:$I$41, C95) + COUNTIFS(Trainee!$H$51:$I65, C95) -> 0
C96: GONG JAC YIK | G96: =COUNTIFS(Trainee!$C$5:$C$57, C96) + COUNTIFS(Trainee!$D$5:$D$51, C96) -> 1 | H96: =COUNTIFS(Trainee!$E$5:$F$51, C96) + COUNTIFS(Trainee!$D$56:$D$57, C96) -> 1 | I96: =COUNTIF(Trainee!$H$5:$I$51, C96) -> 1 | J96: =SUM(G96) + (H96) +(I96) -> 3 | K96: =SUM(MAX(G96 - M96, 0)*2 + MAX(H96 - N96 - O96, 0)*2 + MAX(I96 - P96, 0)*2 + M96*5 + N96*5 + O96*3 + P96*3) -> 6 | M96: =COUNTIF(Trainee!$C$56:$C$57, C96) -> 0 | N96: =COUNTIF(Trainee!$D$56:$D$57, C96) -> 0 | O96: =COUNTIFS(Trainee!$E$10:$F$10, C96) + COUNTIFS(Trainee!$E$31:$F$31, C96) + COUNTIFS(Trainee!$E$41:$F$41, C96) + COUNTIFS(Trainee!$E$51:$F66, C96) -> 0 | P96: =COUNTIFS(Trainee!$H$10:$I$10, C96) + COUNTIFS(Trainee!$H$31:$I$31, C96) + COUNTIFS(Trainee!$H$41:$I$41, C96) + COUNTIFS(Trainee!$H$51:$I66, C96) -> 0
C97: HAIFA MOHAMED SHIRAZ | G97: =COUNTIFS(Trainee!$C$5:$C$57, C97) + COUNTIFS(Trainee!$D$5:$D$51, C97) -> 1 | H97: =COUNTIFS(Trainee!$E$5:$F$51, C97) + COUNTIFS(Trainee!$D$56:$D$57, C97) -> 3 | I97: =COUNTIF(Trainee!$H$5:$I$51, C97) -> 2 | J97: =SUM(G97) + (H97) +(I97) -> 6 | K97: =SUM(MAX(G97 - M97, 0)*2 + MAX(H97 - N97 - O97, 0)*2 + MAX(I97 - P97, 0)*2 + M97*5 + N97*5 + O97*3 + P97*3) -> 13 | M97: =COUNTIF(Trainee!$C$56:$C$57, C97) -> 0 | N97: =COUNTIF(Trainee!$D$56:$D$57, C97) -> 0 | O97: =COUNTIFS(Trainee!$E$10:$F$10, C97) + COUNTIFS(Trainee!$E$31:$F$31, C97) + COUNTIFS(Trainee!$E$41:$F$41, C97) + COUNTIFS(Trainee!$E$51:$F67, C97) -> 1 | P97: =COUNTIFS(Trainee!$H$10:$I$10, C97) + COUNTIFS(Trainee!$H$31:$I$31, C97) + COUNTIFS(Trainee!$H$41:$I$41, C97) + COUNTIFS(Trainee!$H$51:$I67, C97) -> 0
C98: HAMZAH ABDELSALAM ELMEDAKA | G98: =COUNTIFS(Trainee!$C$5:$C$57, C98) + COUNTIFS(Trainee!$D$5:$D$51, C98) -> 1 | H98: =COUNTIFS(Trainee!$E$5:$F$51, C98) + COUNTIFS(Trainee!$D$56:$D$57, C98) -> 3 | I98: =COUNTIF(Trainee!$H$5:$I$51, C98) -> 1 | J98: =SUM(G98) + (H98) +(I98) -> 5 | K98: =SUM(MAX(G98 - M98, 0)*2 + MAX(H98 - N98 - O98, 0)*2 + MAX(I98 - P98, 0)*2 + M98*5 + N98*5 + O98*3 + P98*3) -> 14 | M98: =COUNTIF(Trainee!$C$56:$C$57, C98) -> 0 | N98: =COUNTIF(Trainee!$D$56:$D$57, C98) -> 1 | O98: =COUNTIFS(Trainee!$E$10:$F$10, C98) + COUNTIFS(Trainee!$E$31:$F$31, C98) + COUNTIFS(Trainee!$E$41:$F$41, C98) + COUNTIFS(Trainee!$E$51:$F68, C98) -> 0 | P98: =COUNTIFS(Trainee!$H$10:$I$10, C98) + COUNTIFS(Trainee!$H$31:$I$31, C98) + COUNTIFS(Trainee!$H$41:$I$41, C98) + COUNTIFS(Trainee!$H$51:$I68, C98) -> 1
...

Sheet Weekly IT Requests
A1: Date | B1: Event | C1: Name | D1: Start Time | E1: End Time | F1: Location | G1: Items
A2: 29/11/2025 - 11/30/2025 | B2: Hackathon Workshop 101: How to Win a Hackathon from Scratch | C2: Nurul Nabihah Binti Muhamad Raduan / TP085347@mail.apu.edu.my | D2: 0.33333333 | E2: 0.75 | F2: S-08-02 | G2: Projector x 2
A3: 29/11/2025 | B3: Blockchain 101 Bootcamp | C3: Ng Jian Ming / TP082047@mail.apu.edu.my | D3: 0.33333333 | E3: 0.83333333 | F3: E-09-03 | G3: S-08-01 Projector x2
G4: S-08-02 Projector x2
A5: 01/10/2025 - 12/5/2025 | B5: ICN Promotional Booth | C5: Tanvir Ahmed Khan / tp082974@mail.apu.edu.my | D5: 0.41666667 | E5: 0.70833333 | F5: Atrium @ APU | G5: Projector Stand
G6: Projector Screen
A7: 45985 | B7: Deepavali Lunch | C7: Mr. Navien Rajendran (Admin Staff) | D7: 0.375 | E7: 0.625 | F7: Fine Dining Level 4 | G7: Projector Stand
G8: Projector Screen
A9: 29/11/2025 - 27/11/2025 | B9: CC2 Promotional Booth | C9: Carl Eric Joseph Gideon / 0162432522 Supervisor: Ms. Neeshanti Rhamaroo | D9: 0.41666667 | E9: 0.66666667 | F9: Atrium @ APU | G9: Projector Stand x 2
G10: Projector Screen x 2
A20: Note:
A21: = For Projector & LED Screen, kindly assist them to connect the screen as the equipment is already there.
A22: = If they request to connect the displays with Audio, kindly contact the A/V Team at extension number: 5291 for assistance.
A23: = For Projector Screen & Projector Stand to replace monitor requests. If the representative of the requester asks, kindly contact Mr. Akhil.
A24: = If there is no Projector Screen & Projector Stand left to deploy, kindly contact any Top 3 member or Mr. Akhil for further action.
A25: = For Laser Pointer / Wireless Presenter, kindly contact Mr. Akhil or Mr. Michael should they come to request it.

Sheet Event Standby Requests
A1: Date | B1: Event | C1: Location | D1: Standby From | E1: Standby Till | F1: TA On Standby | G1: TA On Standby (Next shift) | H1: Event actual start | I1: Additional Remarks | J1: Status | X1: Pending
A2: Please Refer to Events Planner on Teams for event standby requests | X2: Acknowledged
X3: Completed
